{"code":"ERR_HTTP_HEADERS_SENT","level":"error","message":"Cannot set headers after they are sent to the client Cannot set headers after they are sent to the client","stack":"Error [ERR_HTTP_HEADERS_SENT]: Cannot set headers after they are sent to the client\n    at ServerResponse.setHeader (node:_http_outgoing:652:11)\n    at ServerResponse.header (D:\\coding\\code_to_share\\shipGpt_front-end\\shipsaas\\server\\node_modules\\express\\lib\\response.js:794:10)\n    at ServerResponse.send (D:\\coding\\code_to_share\\shipGpt_front-end\\shipsaas\\server\\node_modules\\express\\lib\\response.js:174:12)\n    at ServerResponse.json (D:\\coding\\code_to_share\\shipGpt_front-end\\shipsaas\\server\\node_modules\\express\\lib\\response.js:278:15)\n    at loginCommonSection (D:\\coding\\code_to_share\\shipGpt_front-end\\shipsaas\\server\\controllers\\user-controller.js:160:19)\n    at process.processTicksAndRejections (node:internal/process/task_queues:95:5)"}
{"code":"ERR_HTTP_HEADERS_SENT","level":"error","message":"Cannot set headers after they are sent to the client Cannot set headers after they are sent to the client","stack":"Error [ERR_HTTP_HEADERS_SENT]: Cannot set headers after they are sent to the client\n    at ServerResponse.setHeader (node:_http_outgoing:652:11)\n    at ServerResponse.header (D:\\coding\\code_to_share\\shipGpt_front-end\\shipsaas\\server\\node_modules\\express\\lib\\response.js:794:10)\n    at ServerResponse.send (D:\\coding\\code_to_share\\shipGpt_front-end\\shipsaas\\server\\node_modules\\express\\lib\\response.js:174:12)\n    at ServerResponse.json (D:\\coding\\code_to_share\\shipGpt_front-end\\shipsaas\\server\\node_modules\\express\\lib\\response.js:278:15)\n    at loginCommonSection (D:\\coding\\code_to_share\\shipGpt_front-end\\shipsaas\\server\\controllers\\user-controller.js:162:19)\n    at process.processTicksAndRejections (node:internal/process/task_queues:95:5)"}
{"code":"ERR_UNHANDLED_REJECTION","level":"error","message":"This error originated either by throwing inside of an async function without a catch block, or by rejecting a promise which was not handled with .catch(). The promise rejected with the reason \"#<Object>\". This error originated either by throwing inside of an async function without a catch block, or by rejecting a promise which was not handled with .catch(). The promise rejected with the reason \"#<Object>\".","stack":"UnhandledPromiseRejection: This error originated either by throwing inside of an async function without a catch block, or by rejecting a promise which was not handled with .catch(). The promise rejected with the reason \"#<Object>\"."}
{"code":"ERR_UNHANDLED_REJECTION","level":"error","message":"This error originated either by throwing inside of an async function without a catch block, or by rejecting a promise which was not handled with .catch(). The promise rejected with the reason \"#<Object>\". This error originated either by throwing inside of an async function without a catch block, or by rejecting a promise which was not handled with .catch(). The promise rejected with the reason \"#<Object>\".","stack":"UnhandledPromiseRejection: This error originated either by throwing inside of an async function without a catch block, or by rejecting a promise which was not handled with .catch(). The promise rejected with the reason \"#<Object>\"."}
{"code":"ERR_UNHANDLED_REJECTION","level":"error","message":"This error originated either by throwing inside of an async function without a catch block, or by rejecting a promise which was not handled with .catch(). The promise rejected with the reason \"#<Object>\". This error originated either by throwing inside of an async function without a catch block, or by rejecting a promise which was not handled with .catch(). The promise rejected with the reason \"#<Object>\".","name":"UnhandledPromiseRejection","stack":"UnhandledPromiseRejection: This error originated either by throwing inside of an async function without a catch block, or by rejecting a promise which was not handled with .catch(). The promise rejected with the reason \"#<Object>\".\n    at throwUnhandledRejectionsMode (node:internal/process/promises:392:7)\n    at processPromiseRejections (node:internal/process/promises:475:17)\n    at process.processTicksAndRejections (node:internal/process/task_queues:106:32)"}
